<?xml version="1.0" ?>
<sdf version="1.4">
    <model name="box">
        <pose>0.0 0.0 0.0 0.0 0.0 0.0</pose>
        <static>false</static>

        <link name="box_body_${box_name}">
            <inertial>
                <pose>${box_inertial_origin_xyz} ${box_inertial_origin_rpy}</pose>
                <mass>${box_inertial_mass}"</mass>>
                <inertia>
                    <ixx>${box_inertial_inertia_ixx}</ixx>
                    <ixy>${box_inertial_inertia_ixy}</ixy>
                    <ixz>${box_inertial_inertia_ixz}</ixz>
                    <iyy>${box_inertial_inertia_iyy}</iyy>
                    <iyz>${box_inertial_inertia_iyz}</iyz>
                    <izz>${box_inertial_inertia_izz}</izz>
                </inertia>
            </inertial>
            <collision name="box_body_${box_name}_collision">
                <pose>{box_collision_origin_xyz} ${box_collision_origin_rpy}</pose>
                <geometry>
                    <mesh>
                        <uri>package://${package_name}/meshes/${box_collision_geometry_mesh}</uri>
                        <scale>${box_collision_geometry_scale}</scale>
                    </mesh>
                </geometry>
            </collision>
            <visual name="box_body_${box_name}_visual">
                <pose>{box_visual_origin_xyz} ${box_visual_origin_rpy}</pose>
                <geometry>
                    <mesh>
                        <uri>package://${package_name}/meshes/${box_collision_geometry_mesh}</uri>
                        <scale>${box_visual_geometry_scale}</scale>
                    </mesh>
                </geometry>
            </visual>
        </link>

        <link name="cover_frame_${box_name}">
            <inertial>
                <pose>${cover_frame_inertial_origin_xyz} ${cover_frame_inertial_origin_rpy}</pose>
                <mass>${cover_frame_inertial_mass}</mass>>
                <inertia>
                    <ixx>${cover_frame_inertial_inertia_ixx}</ixx>
                    <ixy>${cover_frame_inertial_inertia_ixy}</ixy>
                    <ixz>${cover_frame_inertial_inertia_ixz}</ixz>
                    <iyy>${cover_frame_inertial_inertia_iyy}</iyy>
                    <iyz>${cover_frame_inertial_inertia_iyz}</iyz>
                    <izz>${cover_frame_inertial_inertia_izz}</izz>
                </inertia>
            </inertial>
            <collision name="cover_frame_${box_name}_collision">
                <pose>{cover_frame_collision_origin_xyz} ${cover_frame_collision_origin_rpy}</pose>
                <geometry>
                    <mesh>
                        <uri>package://${package_name}/meshes/${cover_frame_collision_geometry_mesh}</uri>
                        <scale>${cover_frame_collision_geometry_scale}</scale>
                    </mesh>
                </geometry>
            </collision>
            <visual name="cover_frame_${box_name}_visual">
                <pose>{cover_frame_visual_origin_xyz} ${cover_frame_visual_origin_rpy}</pose>
                <geometry>
                    <mesh>
                        <uri>package://${package_name}/meshes/${cover_frame_collision_geometry_mesh}</uri>
                        <scale>${cover_frame_visual_geometry_scale}</scale>
                    </mesh>
                </geometry>
            </visual>
        </link>

        <link name="lever_${box_name}">
            <inertial>
                <pose>${lever_inertial_origin_xyz} ${lever_inertial_origin_rpy}</pose>
                <mass>${lever_inertial_mass}</mass>
                <inertia>
                    <ixx>${lever_inertial_inertia_ixx}</ixx>
                    <ixy>${lever_inertial_inertia_ixy}</ixy>
                    <ixz>${lever_inertial_inertia_ixz}</ixz>
                    <iyy>${lever_inertial_inertia_iyy}</iyy>
                    <iyz>${lever_inertial_inertia_iyz}</iyz>
                    <izz>${lever_inertial_inertia_izz}</izz>
                </inertia>
            </inertial>
            <collision name="cover_frame_${box_name}_collision">
                <pose>{lever_collision_origin_xyz} ${lever_collision_origin_rpy}</pose>
                <geometry>
                    <mesh>
                        <uri>package://${package_name}/meshes/${lever_collision_geometry_mesh}</uri>
                        <scale>${lever_collision_geometry_scale}</scale>
                    </mesh>
                </geometry>
            </collision>
            <visual name="cover_frame_${box_name}_visual">
                <pose>{lever_visual_origin_xyz} ${lever_visual_origin_rpy}</pose>
                <geometry>
                    <mesh>
                        <uri>package://${package_name}/meshes/${lever_collision_geometry_mesh}</uri>
                        <scale>${lever_visual_geometry_scale}</scale>
                    </mesh>
                </geometry>
            </visual>
        </link>

        <link name="cylinder_rod_left_${box_name}">
            <inertial>
                <pose>${cylinder_rod_left_inertial_origin_xyz} ${cylinder_rod_left_inertial_origin_rpy}</pose>
                <mass>${cylinder_rod_left_inertial_mass}</mass>
                <inertia>
                    <ixx>${cylinder_rod_left_inertial_inertia_ixx}</ixx>
                    <ixy>${cylinder_rod_left_inertial_inertia_ixy}</ixy>
                    <ixz>${cylinder_rod_left_inertial_inertia_ixz}</ixz>
                    <iyy>${cylinder_rod_left_inertial_inertia_iyy}</iyy>
                    <iyz>${cylinder_rod_left_inertial_inertia_iyz}</iyz>
                    <izz>${cylinder_rod_left_inertial_inertia_izz}</izz>
                </inertia>
            </inertial>
            <collision name="cylinder_rod_left_${box_name}_collision">
                <pose>{cylinder_rod_left_collision_origin_xyz} ${cylinder_rod_left_collision_origin_rpy}</pose>
                <geometry>
                    <mesh>
                        <uri>package://${package_name}/meshes/${cylinder_rod_left_collision_geometry_mesh}</uri>
                        <scale>${cylinder_rod_left_collision_geometry_scale}</scale>
                    </mesh>
                </geometry>
            </collision>
            <visual name="cylinder_rod_left_${box_name}_visual">
                <pose>{cylinder_rod_left_visual_origin_xyz} ${cylinder_rod_left_visual_origin_rpy}</pose>
                <geometry>
                    <mesh>
                        <uri>package://${package_name}/meshes/${cylinder_rod_left_collision_geometry_mesh}</uri>
                        <scale>${cylinder_rod_left_visual_geometry_scale}</scale>
                    </mesh>
                </geometry>
            </visual>
        </link>

        <link name="cylinder_rod_right_${box_name}">
            <inertial>
                <pose>${cylinder_rod_right_inertial_origin_xyz} ${cylinder_rod_right_inertial_origin_rpy}</pose>
                <mass>${cylinder_rod_right_inertial_mass}</mass>
                <inertia>
                    <ixx>${cylinder_rod_right_inertial_inertia_ixx}</ixx>
                    <ixy>${cylinder_rod_right_inertial_inertia_ixy}</ixy>
                    <ixz>${cylinder_rod_right_inertial_inertia_ixz}</ixz>
                    <iyy>${cylinder_rod_right_inertial_inertia_iyy}</iyy>
                    <iyz>${cylinder_rod_right_inertial_inertia_iyz}</iyz>
                    <izz>${cylinder_rod_right_inertial_inertia_izz}</izz>
                </inertia>
            </inertial>
            <collision name="cylinder_rod_right_${box_name}_collision">
                <pose>{cylinder_rod_right_collision_origin_xyz} ${cylinder_rod_right_collision_origin_rpy}</pose>
                <geometry>
                    <mesh>
                        <uri>package://${package_name}/meshes/${cylinder_rod_right_collision_geometry_mesh}</uri>
                        <scale>${cylinder_rod_right_collision_geometry_scale}</scale>
                    </mesh>
                </geometry>
            </collision>
            <visual name="cylinder_rod_right_${box_name}_visual">
                <pose>{cylinder_rod_right_visual_origin_xyz} ${cylinder_rod_right_visual_origin_rpy}</pose>
                <geometry>
                    <mesh>
                        <uri>package://${package_name}/meshes/${cylinder_rod_right_collision_geometry_mesh}</uri>
                        <scale>${cylinder_rod_right_visual_geometry_scale}</scale>
                    </mesh>
                </geometry>
            </visual>
        </link>

        <link name="cylinder_body_left_${box_name}">
            <inertial>
                <pose>${cylinder_body_left_inertial_origin_xyz} ${cylinder_body_left_inertial_origin_rpy}</pose>
                <mass>${cylinder_body_left_inertial_mass}</mass>
                <inertia>
                    <ixx>${cylinder_body_left_inertial_inertia_ixx}</ixx>
                    <ixy>${cylinder_body_left_inertial_inertia_ixy}</ixy>
                    <ixz>${cylinder_body_left_inertial_inertia_ixz}</ixz>
                    <iyy>${cylinder_body_left_inertial_inertia_iyy}</iyy>
                    <iyz>${cylinder_body_left_inertial_inertia_iyz}</iyz>
                    <izz>${cylinder_body_left_inertial_inertia_izz}</izz>
                </inertia>
            </inertial>
            <collision name="cylinder_body_left_${box_name}_collision">
                <pose>{cylinder_body_left_collision_origin_xyz} ${cylinder_body_left_collision_origin_rpy}</pose>
                <geometry>
                    <mesh>
                        <uri>package://${package_name}/meshes/${cylinder_body_left_collision_geometry_mesh}</uri>
                        <scale>${cylinder_body_left_collision_geometry_scale}</scale>
                    </mesh>
                </geometry>
            </collision>
            <visual name="cylinder_body_left_${box_name}_visual">
                <pose>{cylinder_body_left_visual_origin_xyz} ${cylinder_body_left_visual_origin_rpy}</pose>
                <geometry>
                    <mesh>
                        <uri>package://${package_name}/meshes/${cylinder_body_left_collision_geometry_mesh}</uri>
                        <scale>${cylinder_body_left_visual_geometry_scale}</scale>
                    </mesh>
                </geometry>
            </visual>
        </link>

        <link name="cylinder_body_right_${box_name}">
            <inertial>
                <pose>${cylinder_body_right_inertial_origin_xyz} ${cylinder_body_right_inertial_origin_rpy}</pose>
                <mass>${cylinder_body_right_inertial_mass}</mass>
                <inertia>
                    <ixx>${cylinder_body_right_inertial_inertia_ixx}</ixx>
                    <ixy>${cylinder_body_right_inertial_inertia_ixy}</ixy>
                    <ixz>${cylinder_body_right_inertial_inertia_ixz}</ixz>
                    <iyy>${cylinder_body_right_inertial_inertia_iyy}</iyy>
                    <iyz>${cylinder_body_right_inertial_inertia_iyz}</iyz>
                    <izz>${cylinder_body_right_inertial_inertia_izz}</izz>
                </inertia>
            </inertial>
            <collision name="cylinder_body_right_${box_name}_collision">
                <pose>{cylinder_body_right_collision_origin_xyz} ${cylinder_body_right_collision_origin_rpy}</pose>
                <geometry>
                    <mesh>
                        <uri>package://${package_name}/meshes/${cylinder_body_right_collision_geometry_mesh}</uri>
                        <scale>${cylinder_body_right_collision_geometry_scale}</scale>
                    </mesh>
                </geometry>
            </collision>
            <visual name="cylinder_body_right_${box_name}_visual">
                <pose>{cylinder_body_right_visual_origin_xyz} ${cylinder_body_right_visual_origin_rpy}</pose>
                <geometry>
                    <mesh>
                        <uri>package://${package_name}/meshes/${cylinder_body_right_collision_geometry_mesh}</uri>
                        <scale>${cylinder_body_right_visual_geometry_scale}</scale>
                    </mesh>
                </geometry>
            </visual>
        </link>

        <link name="adapter_plate_${box_name}">
            <inertial>
                <pose>${adapter_plate_inertial_origin_xyz} ${adapter_plate_inertial_origin_rpy}</pose>
                <mass>${adapter_plate_inertial_mass}</mass>
                <inertia>
                    <ixx>${adapter_plate_inertial_inertia_ixx}</ixx>
                    <ixy>${adapter_plate_inertial_inertia_ixy}</ixy>
                    <ixz>${adapter_plate_inertial_inertia_ixz}</ixz>
                    <iyy>${adapter_plate_inertial_inertia_iyy}</iyy>
                    <iyz>${adapter_plate_inertial_inertia_iyz}</iyz>
                    <izz>${adapter_plate_inertial_inertia_izz}</izz>
                </inertia>
            </inertial>
            <collision name="adapter_plate_${box_name}_collision">
                <pose>{adapter_plate_collision_origin_xyz} ${adapter_plate_collision_origin_rpy}</pose>
                <geometry>
                    <mesh>
                        <uri>package://${package_name}/meshes/${adapter_plate_collision_geometry_mesh}</uri>
                        <scale>${adapter_plate_collision_geometry_scale}</scale>
                    </mesh>
                </geometry>
            </collision>
            <visual name="adapter_plate_${box_name}_visual">
                <pose>{adapter_plate_visual_origin_xyz} ${adapter_plate_visual_origin_rpy}</pose>
                <geometry>
                    <mesh>
                        <uri>package://${package_name}/meshes/${adapter_plate_collision_geometry_mesh}</uri>
                        <scale>${adapter_plate_collision_geometry_scale}</scale>
                    </mesh>
                </geometry>
            </visual>
        </link>

        <link name="cover_binder_${box_name}">
            <inertial>
                <pose>${cover_binder_inertial_origin_xyz} ${cover_binder_inertial_origin_rpy}</pose>
                <mass>${cover_binder_inertial_mass}</mass>
                <inertia>
                    <ixx>${cover_binder_inertial_inertia_ixx}</ixx>
                    <ixy>${cover_binder_inertial_inertia_ixy}</ixy>
                    <ixz>${cover_binder_inertial_inertia_ixz}</ixz>
                    <iyy>${cover_binder_inertial_inertia_iyy}</iyy>
                    <iyz>${cover_binder_inertial_inertia_iyz}</iyz>
                    <izz>${cover_binder_inertial_inertia_izz}</izz>
                </inertia>
            </inertial>
            <collision name="cover_binder_${box_name}_collision">
                <pose>{cover_binder_collision_origin_xyz} ${cover_binder_collision_origin_rpy}</pose>
                <geometry>
                    <mesh>
                        <uri>package://${package_name}/meshes/${cover_binder_collision_geometry_mesh}</uri>
                        <scale>${cover_binder_collision_geometry_scale}</scale>
                    </mesh>
                </geometry>
            </collision>
            <visual name="cover_binder_${box_name}_visual">
                <pose>{cover_binder_visual_origin_xyz} ${cover_binder_visual_origin_rpy}</pose>
                <geometry>
                    <mesh filename="package://${package_name}/meshes/${cover_binder_collision_geometry_mesh}"
                      scale="${cover_binder_collision_geometry_scale}"/>
                </geometry>
            </visual>
        </link>

        <joint type="revolute" name="boxcover_joint_${box_name}">
            <pose>${boxcover_joint_origin_xyz} ${boxcover_joint_origin_rpy}</pose>
            <parent>box_body_${box_name}</parent>
            <child>cover_frame_${box_name}</child>
            <axis>
                <xyz>${boxcover_joint_axis_xyz}</xyz>
                <dynamics>
                    <damping>0.3</damping>
                    <frixtion>0.1</frixtion>
                </dynamics>
                <limit>
                    <lower>${boxcover_joint_limit_lower}</lower>
                    <upper>${boxcover_joint_limit_upper}</upper>
                    <effort>${boxcover_joint_limit_effort}</effort>
                    <velocity>${boxcover_joint_limit_velocity}</velocity>
                </limit>
            </axis>
        </joint>

        <joint type="revolute" name="boxlever_joint_${box_name}">
            <pose>${boxlever_joint_origin_xyz} ${boxlever_joint_origin_rpy}</pose>
            <parent>box_body_${box_name}</parent>
            <child>lever_${box_name}</child>
            <axis>
                <xyz>${boxlever_joint_axis_xyz}</xyz>
                <dynamics>
                    <damping>0.3</damping>
                    <frixtion>0.1</frixtion>
                </dynamics>
                <limit>
                    <lower>${boxlever_joint_limit_lower}</lower>
                    <upper>${boxlever_joint_limit_upper}</upper>
                    <effort>${boxlever_joint_limit_effort}</effort>
                    <velocity>${boxlever_joint_limit_velocity}</velocity>
                </limit>
            </axis>
        </joint>

        <joint type="revolute" name="boxcylinder_left_joint_${box_name}">
            <pose>${boxcylinder_left_joint_origin_xyz} ${boxcylinder_left_joint_origin_rpy}</pose>
            <parent>box_body_${box_name}</parent>
            <child>cylinder_rod_left_${box_name}</child>
            <axis>
                <xyz>${boxcylinder_left_joint_axis_xyz}</xyz>
                <dynamics>
                    <damping>0.3</damping>
                    <frixtion>0.1</frixtion>
                </dynamics>
                <limit>
                    <lower>${boxcylinder_left_joint_limit_lower}</lower>
                    <upper>${boxcylinder_left_joint_limit_upper}</upper>
                    <effort>${boxcylinder_left_joint_limit_effort}</effort>
                    <velocity>${boxcylinder_left_joint_limit_velocity}</velocity>
                </limit>
            </axis>
        </joint>

        <joint type="revolute" name="boxcylinder_right_joint_${box_name}">
            <pose>${boxcylinder_right_joint_origin_xyz} ${boxcylinder_right_joint_origin_rpy}</pose>
            <parent>box_body_${box_name}</parent>
            <child>cylinder_rod_right_${box_name}</child>
            <axis>
                <xyz>${boxcylinder_right_joint_axis_xyz}</xyz>
                <dynamics>
                    <damping>0.3</damping>
                    <frixtion>0.1</frixtion>
                </dynamics>
                <limit>
                    <lower>${boxcylinder_right_joint_limit_lower}</lower>
                    <upper>${boxcylinder_right_joint_limit_upper}</upper>
                    <effort>${boxcylinder_right_joint_limit_effort}</effort>
                    <velocity>${boxcylinder_right_joint_limit_velocity}</velocity>
                </limit>
            </axis>
        </joint>

        <joint type="revolute" name="covercylinder_left_joint_${box_name}">
            <pose>${covercylinder_left_joint_origin_xyz} ${covercylinder_left_joint_origin_rpy}</pose>
            <parent>cover_frame_${box_name}</parent>
            <child>cylinder_body_left_${box_name}</child>
            <axis>
                <xyz>${covercylinder_left_joint_axis_xyz}</xyz>
                <dynamics>
                    <damping>0.3</damping>
                    <frixtion>0.1</frixtion>
                </dynamics>
                <limit>
                    <lower>${covercylinder_left_joint_limit_lower}</lower>
                    <upper>${covercylinder_left_joint_limit_upper}</upper>
                    <effort>${covercylinder_left_joint_limit_effort}</effort>
                    <velocity>${covercylinder_left_joint_limit_velocity}</velocity>
                </limit>
            </axis>
        </joint>

        <joint type="revolute" name="covercylinder_right_joint_${box_name}">
            <pose>${covercylinder_right_joint_origin_xyz} ${covercylinder_right_joint_origin_rpy}</pose>
            <parent>cover_frame_${box_name}</parent>
            <child>cylinder_body_right_${box_name}</child>
            <axis>
                <xyz>${covercylinder_right_joint_axis_xyz}</xyz>
                <dynamics>
                    <damping>0.3</damping>
                    <frixtion>0.1</frixtion>
                </dynamics>
                <limit>
                    <lower>${covercylinder_right_joint_limit_lower}</lower>
                    <upper>${covercylinder_right_joint_limit_upper}</upper>
                    <effort>${covercylinder_right_joint_limit_effort}</effort>
                    <velocity>${covercylinder_right_joint_limit_velocity}</velocity>
                </limit>
            </axis>
        </joint>

        <joint type="prismatic" name="cylinder_left_joint_${box_name}">
            <pose>${cylinder_left_joint_origin_xyz} ${cylinder_left_joint_origin_rpy}</pose>
            <parent>cylinder_rod_left_${box_name}</parent>
            <child>cylinder_body_left_${box_name}</child>
            <axis>
                <xyz>${cylinder_left_joint_axis_xyz}</xyz>
                <dynamics>
                    <damping>0.3</damping>
                    <frixtion>0.1</frixtion>
                </dynamics>
                <limit>
                    <lower>${cylinder_left_joint_limit_lower}</lower>
                    <upper>${cylinder_left_joint_limit_upper}</upper>
                    <effort>${cylinder_left_joint_limit_effort}</effort>
                    <velocity>${cylinder_left_joint_limit_velocity}</velocity>
                </limit>
            </axis>
        </joint>

        <joint type="prismatic" name="cylinder_right_joint_${box_name}">
            <pose>${cylinder_right_joint_origin_xyz} ${cylinder_right_joint_origin_rpy}</pose>
            <parent>cylinder_rod_right_${box_name}</parent>
            <child>cylinder_body_right_${box_name}</child>
            <axis>
                <xyz>${cylinder_right_joint_axis_xyz}</xyz>
                <dynamics>
                    <damping>0.3</damping>
                    <frixtion>0.1</frixtion>
                </dynamics>
                <limit>
                    <lower>${cylinder_right_joint_limit_lower}</lower>
                    <upper>${cylinder_right_joint_limit_upper}</upper>
                    <effort>${cylinder_right_joint_limit_effort}</effort>
                    <velocity>${cylinder_right_joint_limit_velocity}</velocity>
                </limit>
            </axis>
        </joint>

        <joint type="fixed" name="boxadapterplate_joint_${box_name}">
            <pose>${adapter_plate_joint_origin_xyz} ${adapter_plate_joint_origin_rpy}</pose>
            <parent>box_body_${box_name}</parent>
            <child>adapter_plate_${box_name}</child>
        </joint>

        <joint type="fixed" name="coverbinder_joint_${box_name}">
            <pose>${cover_binder_joint_origin_xyz} ${cover_binder_joint_origin_rpy}</pose>
            <parent>cover_frame_${box_name}</parent>
            <child>cover_binder_${box_name}</child>
        </joint>

    </model>
</sdf>